Workbook
Name DC_001: 'DC Acilia Housing Dati'!$B$5:$G$132
Name DC_002: 'DC Acilia Housing VoIP'!$B$5:$H$132
Name DC_003: 'DC Pomezia Housing Dati'!$B$5:$H$132
Name DC_004: 'DC Pomezia Housing Voip'!$B$5:$H$132
Name DC_005: 'DC Acilia Housing Mng'!$B$5:$H$36
Name DC_006: 'DC S.Stefano Housing Dati'!$B$4:$H$36
Name DC_006: 'DC S.Stefano Housing Mng'!$B$4:$H$36
Name DC_006: 'DC S.Stefano Housing Voip'!$B$4:$G$36
Name DC_006: 'DC Pomezia Housing Mng'!$B$4:$H$36
Name Iaas_000_Waf: 'WAF-Leonardo'!$B$4:$H$260
Name Iaas_001: 'WAF-Leonardo'!$B$4:$H$260
Name Iaas_001: '10.58.1.0 |24'!$B$4:$H$260
Name Iaas_003: '10.58.3.0 |24'!$B$4:$H$260
Name Iaas_004: '10.58.4.0 |24'!$B$4:$H$260
Name Iaas_010: '10.58.10.0 |24'!$B$4:$H$260
Name Iaas_020: '10.58.20.0 |24 '!$B$4:$H$260
Name Iaas_025: '10.58.25.0 |24'!$B$4:$H$260
Name Iaas_030: '10.58.30.0 |24'!$B$4:$H$260
Name Iaas_031: '10.58.31.0 |24'!$B$4:$H$260
Name Iaas_032: '10.58.32.0 |24'!$B$4:$H$260
Name Iaas_033: '10.58.33.0 |24'!$B$4:$H$260
Name Iaas_040: '10.58.40.0 |24'!$B$4:$H$260
Name Iaas_041: '10.58.41.0 |24'!$B$4:$H$260
Name Iaas_050: '10.58.50.0 |24'!$B$4:$H$260
Name Iaas_051: '10.58.51.0 |24'!$B$4:$H$260
Name Iaas_061: '10.58.61.0 |24'!$B$4:$H$260
Name Iaas_065: '10.58.65.0 |24'!$B$4:$H$260
Name Iaas_073: '10.58.73.0 |24'!$B$4:$H$260
Name Iaas_080: '10.58.80.0 |24 '!$B$4:$H$260
Name Iaas_085: '10.58.85.0 |24 '!$B$4:$H$260
Name Iaas_090: '10.58.90.0 |24'!$B$4:$H$260
Name Iaas_091: '10.58.91.0 |24'!$B$4:$H$260
Name Iaas_093: '10.58.118.0 |24 '!$B$4:$G$260
Name Iaas_093: '10.58.131.0 |24'!$B$4:$H$260
Name Iaas_093: '10.58.133.0 |24'!$B$4:$H$260
Name Iaas_093: '10.58.134.0 |24'!$B$4:$H$260
Name Iaas_093: '10.58.140.0 |24'!$B$4:$H$260
Name Iaas_093: '10.58.150.0 |24'!$B$4:$H$260
Name Iaas_093: '10.58.155.0 |24'!$B$4:$H$260
Name Iaas_093: '10.58.160.0 |24'!$B$4:$H$260
Name Iaas_093: '10.58.161.0 |24'!$B$4:$H$260
Name Iaas_093: '10.58.162.0 |24'!$B$4:$G$260
Name Iaas_093: '10.58.163.0 |24'!$B$4:$H$260
Name Iaas_093: '10.58.170.0 |24'!$B$4:$H$260
Name Iaas_093: '10.58.171.0 |24'!$B$4:$H$260
Name Iaas_093: '10.58.180.0 |24'!$B$4:$H$260
Name Iaas_093: '10.58.181.0 |24'!$B$4:$H$260
Name Iaas_093: '10.58.191.0 |24'!$B$4:$H$260
Name Iaas_093: '10.58.200.0 |24'!$B$4:$H$260
Name Iaas_093: '10.58.210.0 |24'!$B$4:$H$260
Name Iaas_093: '10.58.215.0 |24'!$B$4:$H$260
Name Iaas_093: '10.58.220.0 |24'!$B$4:$H$260
Name Iaas_093: '10.58.221.0 |24'!$B$4:$H$260
Name Iaas_093: '10.58.223.0 |24'!$B$4:$H$260
Name Iaas_093: '10.58.93.0 |24 '!$B$4:$H$260

Sheet Tenant
B2: in giallo le info da verificare
B4: TGU/ID | C4: Tenant/Ambienti | D4: Stato | E4: IP | F4: Zona | G4: Commento | H4: Fonte | I4: Note
B5: PSN 02 84 27 23 | C5: Tenant di Sicurezza IN COMUNE A PRODUZIONE E A TEST/COLLAUDO | D5: Attivo | E5: 198.18.226.3 198.18.225.23/32 198.18.225.24/32 | F5: Iaas
B7: PSN 02 95 78 77 | C7: Tenant Produzione - IaaS | D7: Attivo | E7: 198.18.226.25 | F7: Iaas | H7: PannelloAcceso | I7: Tenant creato a febbraio 2025 con Overcommit in sostituzione del precedente
B8: PSN 02 88 49 71 | C8: Tenant Produzione - Paas | D8: Attivo | F8: Paas | H8: Mail di Pietro Filipponi - Richiesta Staging Area
B9: PSN 02 88 63 45 | C9: Housing ACILIA | D9: Attivo | F9: Housing
B10: PSN 02 88 63 38 | C10: Housing POMEZIA | D10: Attivo | F10: Housing
B12: PSN 02 99 31 65 | C12: Tenant Test/Collaudo - Iaas | D12: Attivo | E12: 198.18.226.17 | F12: Iaas | H12: PannelloAcceso
B13: PSN 02 87 91 04 | C13: Tenant Test/Collaudo - Paas | D13: Attivo | F13: Paas | H13: Mail di Pietro Filipponi - Richiesta Staging Area
B15: PSN02884971-?? | C15: Produzione Paas - Staging | D15: Attivo | F15: Paas-Staging | H15: Mail di Pietro Filipponi - Richiesta Staging Area | I15: Le staging area hanno id tenant uguale al Paas con aggiunta di -??
B16: PSN02879104-?? | C16: Collaudo Paas - Staging | D16: Attivo | F16: Paas-Staging | H16: Mail di Pietro Filipponi - Richiesta Staging Area | I16: Le staging area hanno id tenant uguale al Paas con aggiunta di -??
B19: COMPLETARE QUADRO CON MIAL FILIPPONI
A21: ? | B21: PSN-8173691000 | F21: Housing??? | H21: Mail di assistenza PSN
A22: ? | B22: PSN02687922 | E22: 198.18.226.4
A23: ? | B23: PSN02830780 | D23: Disabilitato
B25: PSN03137816 PaaS DB associato al tenant si Produzione ISED di Santo Stefano Ticino (PSN03081639)
B26: PSN03137802 PaaS DB associato al tenant ex SPC Cloud di Santo Stefano Ticino (PSN03033633)
B27: PSN03081651 Tenant Test e Collaudo ISED su Santo Stefano Ticino | G27: PSN03137816 | H27: PaaS DB Produzione ISED – Santo Stefano Ticino
B28: PSN03081639 Tenant Produzione ISED su Santo Stefano Ticino | G28: PSN03137802 | H28: PaaS DB ex SPC Cloud – Santo Stefano Ticino
B29: PSN03033633 Tenant SPC su Santo Stefano Ticino | G29: PSN03081651 | H29: Tenant Test e Collaudo ISED – Santo Stefano Ticino
B30: PSN03003325 Tenant di sicurezza su Santo Stefano Ticino | G30: PSN03081639 | H30: Tenant Produzione ISED – Santo Stefano Ticino
B31: PSN02954035 Housing Santo Stefano Ticino | G31: PSN03033633 | H31: Tenant ex SPC Cloud – Santo Stefano Ticino
G32: PSN03003325 | H32: Tenant di sicurezza – Santo Stefano Ticino
B33: PSN02993165 Tenant di test e collaudo ISED | G33: PSN02954035 | H33: Housing Santo Stefano Ticino
B34: PSN02957877 Tenant di produzione ISED | G34: PSN02993165 | H34: Tenant Test e Collaudo ISED – Acilia/Pomezia
G35: PSN02957877 | H35: Tenant Produzione ISED – Acilia/Pomezia
B36: PSN02886345 Housing Acilia | G36: PSN02954035 | H36: Housing Santo Stefano Ticino
B37: PSN02886338 Housing Pomezia | G37: PSN02886345 | H37: Housing Acilia
G38: PSN02886338 | H38: Housing Pomezia
B39: PSN02884971 PaaS DB produzione ISED | G39: PSN02884971 | H39: PaaS DB Produzione ISED – Acilia/Pomezia
B40: PSN02879104 PaaS DB test e collaudo ISED | G40: PSN02879104 | H40: PaaS DB Test e Collaudo ISED – Acilia/Pomezia
G41: PSN02842723 | H41: Tenant di sicurezza – Acilia/Pomezia
B42: Ciao, | G42: PSN02687931 | H42: PaaS DB ex SPC Cloud – Acilia/Pomezia
B43: Pietro | G43: PSN02687922 | H43: Tenant ex SPC Cloud – Acilia/Pomezia

Sheet Nomenclatore_1.1
B2: Sito (*) | J2: Tenant (*) | O2: Dominio | U2: Area | AA2: Accesso | AF2: Ambito | AK2: Tipo Macchina (*)
B3: psn | C3: se riguarda tutti i DC convolti: Acilia (ac), Pomezia (pm) e S.Stefano | J3: prod | K3: PSN PRODUZIONE | P3: don't care | V3: don't care | AB3: don't care | AG3: don't care | AK3: ad
B4: bc | C4: se riguarda SOLO i DC di Business Continuity: Acilia (ac), Pomezia (pm) | J4: test | K4: PSN TEST&COLLAUDO | O4: sie | P4: se riguarda l'intera piattaforma SIE | U4: app | V4: se ricade nell'area APPLICATIVA | AA4: int | AB4: se la risorsa è accessibile SOLO dall'INTERNO (Intranet) | AF4: soeu | AG4: se la risorsa è funzionale alle SOLE componenti di SALA OPERATIVA DI EMERGENZA/URGENZA | AK4: ast
B5: dr | C5: se riguarda il SOLO DC di Disaster Recovery: S.Stefano | J5: ci | K5: SVIL Continuous Integration | O5: eu | P5: se riguarda i SOLI sistemi di EMERGENZA/URGENZA | U5: tel | V5: se ricade nell'area TELEFONICA | AA5: ext | AB5: se la risorsa è accessibile SOLO dall'ESTERNO (Internet) | AF5: soneu | AG5: se la risorsa è funzionale alle SOLE componenti di SALA OPERATIVA DI NON EMERGENZA/URGENZA | AK5: cas
B6: ac | C6: se riguarda il SOLO DC di BC Acilia (ac) | J6: demo | K6: SVIL Demo | O6: neu | P6: se riguarda i SOLI sistemi di NON EMERGENZA/URGENZA | U6: rec | V6: se ricade nell'area di RECORDING | AA6: mob | AB6: se la risorsa è accessibile SOLO dalla Rete MOBILE | AF6: ws | AG6: se la risorsa è funzionale alle SOLE componenti WEB SERVICE | AK6: chk
B7: pm | C7: se riguarda il SOLO DC di BC Pomezia (pm) | O7: pub | P7: se riguarda i SOLI sistemi Esposti su internet | AF7: fe | AG7: se la risorsa è funzionale alle SOLE componenti di FRONTEND | AK7: ctrl
B8: svil | C8: se riguarda l'ambiente SVILUPPO | O8: tb | P8: se riguarda i SOLI sistemi Tablet | AF8: tbt | AG8: se la risorsa è funzionale alle SOLE componenti MOBILE | AK8: db
AF9: auth | AG9: se la risorsa è funzionale alle SOLE componenti CAS di autenticazione | AK9: dbcll | AL9: call logging
AF10: cache | AG10: se la risorsa è funzionale alle SOLE componenti di INFINISPAN | AK10: dbdoc
AK11: dc
AK12: dcmob
AK13: dcpdl
AK14: dcsvr
AK15: dhcp
AK16: dns
AK17: dns-dhcp
AK18: elx
B19: N.B.: Per i proxy deve essere valorizzata la colonna DOMINIO perché a parità di accesso deve essere possibile distinguere il gruppo di sistemi (definito dominio) verso i quali devono essere inoltrate le richieste Per i worker e i controller deve essere valorizzata la colonna AMBITO per poter distinguere il settore specifico di competenza anche a parità di Dominio o Accesso | AK19: evoip
AK20: ipa
B21: Macchina | J21: =+B2 -> Sito (*) | K21: =+J2 -> Tenant (*) | L21: =+O2 -> Dominio | M21: =+U2 -> Area | N21: =+AA2 -> Accesso | O21: =+AF2 -> Ambito | P21: =+AK2 -> Tipo Macchina (*) | Q21: Progr (*) | S21: Nome | W21: Nomi host con eccezioni | X21: Note | Y21: DISPOSITIVO | AK21: ippsrv | AL21: repository
B22: Dominio mv di servizio e gestione | D22: DHCP PDL | J22: bc | K22: prod | P22: dhcp | Q22: XX | S22: =CONCATENATE(J22,"-",K22,IF(L22="","",CONCATENATE("-",L22)),IF(M22="","",CONCATENATE("-",M22)),IF(N22="","",CONCATENATE("-",N22)),IF(O22="","",CONCATENATE("-",O22)),IF(P22="","",CONCATENATE("-",P22)),IF(Q22="","",Q22)) -> bc-prod-dhcpXX | X22: ??Contenuto in VM DNS? | Y22: svr | AK22: kib
D23: DNS INTERNO | J23: bc | K23: prod | P23: dns-dhcp | Q23: XX | S23: =CONCATENATE(J23,"-",K23,IF(L23="","",CONCATENATE("-",L23)),IF(M23="","",CONCATENATE("-",M23)),IF(N23="","",CONCATENATE("-",N23)),IF(O23="","",CONCATENATE("-",O23)),IF(P23="","",CONCATENATE("-",P23)),IF(Q23="","",Q23)) -> bc-prod-dns-dhcpXX | X23: Contiene svr DHCP | Y23: pdl | AK23: mail
D24: SSO di sistema | J24: bc | K24: prod | P24: ipa | Q24: XX | S24: =CONCATENATE(J24,"-",K24,IF(L24="","",CONCATENATE("-",L24)),IF(M24="","",CONCATENATE("-",M24)),IF(N24="","",CONCATENATE("-",N24)),IF(O24="","",CONCATENATE("-",O24)),IF(P24="","",CONCATENATE("-",P24)),IF(Q24="","",Q24)) -> bc-prod-ipaXX | X24: IP associato | Y24: pdlmob | AK24: micc
D25: Sistema di monitoraggio Nagios | J25: bc | K25: prod | P25: nagios | Q25: XX | S25: =CONCATENATE(J25,"-",K25,IF(L25="","",CONCATENATE("-",L25)),IF(M25="","",CONCATENATE("-",M25)),IF(N25="","",CONCATENATE("-",N25)),IF(O25="","",CONCATENATE("-",O25)),IF(P25="","",CONCATENATE("-",P25)),IF(Q25="","",Q25)) -> bc-prod-nagiosXX | X25: IP associato, VM da creare | AK25: mon
D26: Sistema di monitoraggio Check MK | J26: bc | K26: prod | P26: chk | Q26: XX | S26: =CONCATENATE(J26,"-",K26,IF(L26="","",CONCATENATE("-",L26)),IF(M26="","",CONCATENATE("-",M26)),IF(N26="","",CONCATENATE("-",N26)),IF(O26="","",CONCATENATE("-",O26)),IF(P26="","",CONCATENATE("-",P26)),IF(Q26="","",Q26)) -> bc-prod-chkXX | X26: IP associato | AK26: nagios
D27: Sistema di monitoraggio Kibana | J27: bc | K27: prod | P27: kib | Q27: XX | S27: =CONCATENATE(J27,"-",K27,IF(L27="","",CONCATENATE("-",L27)),IF(M27="","",CONCATENATE("-",M27)),IF(N27="","",CONCATENATE("-",N27)),IF(O27="","",CONCATENATE("-",O27)),IF(P27="","",CONCATENATE("-",P27)),IF(Q27="","",Q27)) -> bc-prod-kibXX | X27: IP associato | AK27: nas
D28: Sistema di monitoraggio Elastic Search | J28: bc | K28: prod | P28: elx | Q28: XX | S28: =CONCATENATE(J28,"-",K28,IF(L28="","",CONCATENATE("-",L28)),IF(M28="","",CONCATENATE("-",M28)),IF(N28="","",CONCATENATE("-",N28)),IF(O28="","",CONCATENATE("-",O28)),IF(P28="","",CONCATENATE("-",P28)),IF(Q28="","",Q28)) -> bc-prod-elxXX | X28: IP associato | AK28: oas
D29: Domain Controller - Server di dominio Svr | J29: bc | K29: prod | P29: dcsvr | Q29: XX | S29: =CONCATENATE(J29,"-",K29,IF(L29="","",CONCATENATE("-",L29)),IF(M29="","",CONCATENATE("-",M29)),IF(N29="","",CONCATENATE("-",N29)),IF(O29="","",CONCATENATE("-",O29)),IF(P29="","",CONCATENATE("-",P29)),IF(Q29="","",Q29)) -> bc-prod-dcsvrXX | W29: bc-p-dcsrvX | X29: IP associato | AK29: proxy
D30: Domain Controller - Server di dominio PdL | J30: bc | K30: prod | P30: dcpdl | Q30: XX | S30: =CONCATENATE(J30,"-",K30,IF(L30="","",CONCATENATE("-",L30)),IF(M30="","",CONCATENATE("-",M30)),IF(N30="","",CONCATENATE("-",N30)),IF(O30="","",CONCATENATE("-",O30)),IF(P30="","",CONCATENATE("-",P30)),IF(Q30="","",Q30)) -> bc-prod-dcpdlXX | W30: bc-p-dcpdlX | X30: IP associato | AK30: pvs | AL30: provisioning
B31: Dominio mv applicative servizi EU non esposti su Internet | D31: Vip eu | J31: bc | K31: prod | L31: eu | N31: int | P31: vip | S31: =CONCATENATE(J31,"-",K31,IF(L31="","",CONCATENATE("-",L31)),IF(M31="","",CONCATENATE("-",M31)),IF(N31="","",CONCATENATE("-",N31)),IF(O31="","",CONCATENATE("-",O31)),IF(P31="","",CONCATENATE("-",P31)),IF(Q31="","",Q31)) -> bc-prod-eu-int-vip | X31: eusie118.psn-ares.it | AK31: sn
D32: Active Directory - LDAP | J32: bc | K32: prod | M32: app | P32: ad | Q32: XX | S32: =CONCATENATE(J32,"-",K32,IF(L32="","",CONCATENATE("-",L32)),IF(M32="","",CONCATENATE("-",M32)),IF(N32="","",CONCATENATE("-",N32)),IF(O32="","",CONCATENATE("-",O32)),IF(P32="","",CONCATENATE("-",P32)),IF(Q32="","",Q32)) -> bc-prod-app-adXX | W32: bc-p-app-adX | X32: IP associato | AK32: snrid
D33: Mail Exchanger (Relay) | J33: bc | K33: prod | P33: mail | Q33: XX | S33: =CONCATENATE(J33,"-",K33,IF(L33="","",CONCATENATE("-",L33)),IF(M33="","",CONCATENATE("-",M33)),IF(N33="","",CONCATENATE("-",N33)),IF(O33="","",CONCATENATE("-",O33)),IF(P33="","",CONCATENATE("-",P33)),IF(Q33="","",Q33)) -> bc-prod-mailXX | X33: Non Creata | AK33: switch
D34: Reverse Proxy | J34: bc | K34: prod | L34: eu | P34: proxy | Q34: XX | S34: =CONCATENATE(J34,"-",K34,IF(L34="","",CONCATENATE("-",L34)),IF(M34="","",CONCATENATE("-",M34)),IF(N34="","",CONCATENATE("-",N34)),IF(O34="","",CONCATENATE("-",O34)),IF(P34="","",CONCATENATE("-",P34)),IF(Q34="","",Q34)) -> bc-prod-eu-proxyXX | X34: IP associato | AK34: tdm
D35: Controller AS | J35: bc | K35: prod | O35: soeu | P35: ctrl | Q35: XX | S35: =CONCATENATE(J35,"-",K35,IF(L35="","",CONCATENATE("-",L35)),IF(M35="","",CONCATENATE("-",M35)),IF(N35="","",CONCATENATE("-",N35)),IF(O35="","",CONCATENATE("-",O35)),IF(P35="","",CONCATENATE("-",P35)),IF(Q35="","",Q35)) -> bc-prod-soeu-ctrlXX | X35: IP associato | AK35: vip
D36: Worker di gestione | J36: bc | K36: prod | O36: soeu | P36: wrk | Q36: XX | S36: =CONCATENATE(J36,"-",K36,IF(L36="","",CONCATENATE("-",L36)),IF(M36="","",CONCATENATE("-",M36)),IF(N36="","",CONCATENATE("-",N36)),IF(O36="","",CONCATENATE("-",O36)),IF(P36="","",CONCATENATE("-",P36)),IF(Q36="","",Q36)) -> bc-prod-soeu-wrkXX | X36: IP associato | AK36: wrk
D37: Worker di autenticazione | J37: bc | K37: prod | L37: eu | O37: auth | P37: wrk | Q37: XX | S37: =CONCATENATE(J37,"-",K37,IF(L37="","",CONCATENATE("-",L37)),IF(M37="","",CONCATENATE("-",M37)),IF(N37="","",CONCATENATE("-",N37)),IF(O37="","",CONCATENATE("-",O37)),IF(P37="","",CONCATENATE("-",P37)),IF(Q37="","",Q37)) -> bc-prod-eu-auth-wrkXX | X37: IP associato | AK37: nfs | AL37: condivisione risorse - ortofoto
D38: Worker di servizio | J38: bc | K38: prod | L38: eu | O38: cache | P38: wrk | Q38: XX | S38: =CONCATENATE(J38,"-",K38,IF(L38="","",CONCATENATE("-",L38)),IF(M38="","",CONCATENATE("-",M38)),IF(N38="","",CONCATENATE("-",N38)),IF(O38="","",CONCATENATE("-",O38)),IF(P38="","",CONCATENATE("-",P38)),IF(Q38="","",Q38)) -> bc-prod-eu-cache-wrkXX | X38: IP associato | AK38: biai
D39: Worker di integrazione telefonica | S39: =CONCATENATE(J39,"-",K39,IF(L39="","",CONCATENATE("-",L39)),IF(M39="","",CONCATENATE("-",M39)),IF(N39="","",CONCATENATE("-",N39)),IF(O39="","",CONCATENATE("-",O39)),IF(P39="","",CONCATENATE("-",P39)),IF(Q39="","",Q39)) -> - | AK39: core
D40: Ortofoto | J40: bc | K40: prod | L40: eu | P40: nfs | S40: =CONCATENATE(J40,"-",K40,IF(L40="","",CONCATENATE("-",L40)),IF(M40="","",CONCATENATE("-",M40)),IF(N40="","",CONCATENATE("-",N40)),IF(O40="","",CONCATENATE("-",O40)),IF(P40="","",CONCATENATE("-",P40)),IF(Q40="","",Q40)) -> bc-prod-eu-nfs
B41: Dominio mv applicative NON EU | D41: VIP non eu | J41: bc | K41: prod | L41: neu | N41: int | P41: vip | S41: =CONCATENATE(J41,"-",K41,IF(L41="","",CONCATENATE("-",L41)),IF(M41="","",CONCATENATE("-",M41)),IF(N41="","",CONCATENATE("-",N41)),IF(O41="","",CONCATENATE("-",O41)),IF(P41="","",CONCATENATE("-",P41)),IF(Q41="","",Q41)) -> bc-prod-neu-int-vip | X41: neusie118.psn-ares.it
...

Sheet DB
L1: 2024.06.10 - PSN PaaS DB Oracle - Template info Clienti V7 - Ares118 wave2.xlsx | M1: Ultima richiesta per Paas
A2: Database
A3: IP da Tenant Ised | B3: IP da SED | C3: Porta | D3: ServiceName | E3: SID | F3: User | G3: DB Unique Name | H3: PDB | I3: Tenant | J3: Etichetta
A4: 100.67.102.9 | B4: 10.58.3.252 | C4: 1521 | D4: s_sieprod_pdb_sie118.psnexaac.it | E4: - | F4: pa_admin | G4: SIEPROD | H4: SIE118 | I4: PSN02884971 | J4: Prod
A5: 100.67.102.9 | B5: 10.58.3.252 | C5: 1521 | D5: s_sieprod_pdb_dwh118.psnexaac.it | E5: - | F5: pa_admin | G5: SIEPROD | H5: DWH118 | I5: PSN02884971 | J5: Prod DWH
A6: 100.67.102.9 | B6: 10.58.3.252 | C6: 1521 | D6: s_sieform_pdb_testsie.psnexaac.it | E6: - | F6: pa_admin | G6: SIEFORM | H6: TESTSIE | I6: PSN02879104 | J6: TEST-COLL EU
A7: 100.67.102.9 | B7: 10.58.3.252 | C7: 1521 | D7: s_sieform_pdb_svilsie.psnexaac.it | F7: pa_admin | G7: SIEFORM | H7: SVILSIE | I7: PSN02879104 | J7: TEST-COLL EU
A8: 100.67.102.9 | B8: 10.58.3.252 | C8: 1521 | D8: s_sieform_pdb_demosie.psnexaac.it | F8: pa_admin | G8: SIEFORM | H8: DEMOSIE | I8: PSN02879104 | J8: TEST-COLL EU
A9: 100.67.102.9 | B9: 10.58.3.252 | C9: 1521 | D9: s_sieform_pdb_dwhform.psnexaac.it | F9: pa_admin | G9: SIEFORM | H9: DWHFORM | I9: PSN02879104 | J9: TEST-COLL EU
A11: Area di Staging
A12: IP da Tenant Ised | B12: IP da SED | C12: Porta | D12: Utente | G12: Visibile da:
A13: 192.18.226.16 | B13: 10.58.3.252 | C13: 8022 | D13: vmtranster118prod | G13: SIE118 e DWH118
A14: 192.18.226.16 | B14: 10.58.3.252 | C14: 8022 | D14: vmtranster118test | G14: TEST/SVIL/DEMO/DWHForm

Sheet Summary
B2: Anagrafica delle subnet
A3: HOUSING + SEDI CLIENTE
A4: Nome | C4: Subnet | D4: ID | E4: Descrizione
A5: #VALUE! | B5: DC Acilia Housing Dati | C5: 192.168.210.0/25 - 255.255.255.128 | D5: 001 | E5: Dati
A6: #VALUE! | B6: DC Acilia Housing Voip | C6: 192.168.210.128/25 - 255.255.255.128 | D6: 002 | E6: VoIP
A7: #VALUE! | B7: DC Acilia Housing Mng | C7: 192.168.241.0/27 - 255.255.255.224 | D7: 003 | E7: Management
A8: #VALUE! | B8: DC Pomezia Housing Dati | C8: 192.168.220.0/25 - 255.255.255.128 | D8: 004 | E8: Dati
A9: #VALUE! | B9: DC Pomezia Housing Voip | C9: 192.168.220.128/25 - 255.255.255.128 | D9: 005 | E9: VoIP
A10: #VALUE! | B10: DC Pomezia Housing Mng | C10: 192.168.241.32/27 - 255.255.255.224 | D10: 006 | E10: Management
A11: #VALUE! | B11: DC S.Stefano Housing Dati | C11: 192.168.230.0/25 - 255.255.255.128 | D11: 101 | E11: Dati
A12: #VALUE! | B12: DC S.Stefano Housing Voip | C12: 192.168.230.128/25 - 255.255.255.128 | D12: 102 | E12: VoIP
A13: #VALUE! | B13: DC S.Stefano Housing Mng | C13: 192.168.241.64/27 - 255.255.255.224 | D13: 103 | E13: Management
A14: #VALUE! | B14: CO Roma S.Camillo Dati | C14: 192.168.181.0/24 - 255.255.255.0 | D14: 007 | E14: Dati
A15: #VALUE! | B15: CO Roma S.Camillo Voip | C15: 192.168.191.0/24 - 255.255.255.0 | D15: 008 | E15: VoIP
A16: #VALUE! | B16: CO Roma S.Camillo Voip DR | C16: 192.168.211.0/24 - 255.255.255.0 | D16: 108 | E16: VoIP
... A30: #VALUE! | B30: CO Anagnina1 Voip | C30: 192.168.196.0/24 - 255.255.255.0 | D30: 018 | E30: VoIP
B31: CO Anagnina1 Voip DR | C31: 192.168.217.0/24 - 255.255.255.0 ??? | D31: 118 ?
B32: CO Anagnina2 Dati | E32: Dati
B33: CO Anagnina2 Voip | E33: VoIP
B34: CO Anagnina2 Roma Nuova Centrale Operativa (Ipotetica) | C34: 192.168.212.0/24 - 255.255.255.0 | D34: ??? | E34: VoIP
A35: TENANT ISED SUPERNET 10.58.0.0/16
A36: IAAS - PRODUZIONE EMERGENZA/URGENZA - 10.58.0.0 /18
A37: #VALUE! | B37: VNET_vip_10-58-1-0 | C37: 10.58.1.0/24 - 255.255.255.0 | D37: 019 | E37: VIP L4 su edge router
A38: #VALUE! | B38: VNET_idm-ipa_10-58-3-0 | C38: 10.58.3.0/24 - 255.255.255.0 | D38: 020 | E38: Ipa, SSO
A39: #VALUE! | B39: VNET_idm-ad_10-58-4-0 | C39: 10.58.4.0/24 - 255.255.255.0 | D39: 021 | E39: Gruppo AD - LDAP / GPO PDL e TABLET - DHCP PDL
A40: #VALUE! | B40: VNET_monitor_10-58-10-0 | C40: 10.58.10.0/24 - 255.255.255.0 | D40: 022 | E40: Monitoraggio, mail relay
A41: #VALUE! | B41: VNET_sist-tel-eu_10-58-20-0 | C41: 10.58.20.0/24 - 255.255.255.0 | D41: 023 | E41: Sist. Telefonico - EU
A42: #VALUE! | B42: VNET_sist-reg-eu_10-58-25-0 | C42: 10.58.25.0/24 - 255.255.255.0 | D42: 024 | E42: Sist. Registrazione - EU
A43: #VALUE! | B43: VNET_proxy-eu-app_10-58-30-0 | C43: 10.58.30.0/24 - 255.255.255.0 | D43: 025 | E43: Gruppo Proxy EU
A44: #VALUE! | B44: VNET_backend-eu_10-58-31-0 | C44: 10.58.31.0/24 - 255.255.255.0 | D44: 026 | E44: Gruppo Backend - EU
A45: #VALUE! | B45: VNET_db-eu_10-58-32-0 | C45: 10.58.32.0/24 - 255.255.255.0 | D45: 027 | E45: Database Applicazione
A46: #VALUE! | B46: VNET_eu-auth_10-58-33-0 | C46: 10.58.33.0/24 - 255.255.255.0 | D46: 028 | E46: Gruppo Auth SIE (Trasversale per SSO in EU/NEU)
A47: #VALUE! | B47: VNET_proxy-eu-tbl_10-58-40-0 | C47: 10.58.40.0/24 - 255.255.255.0 | D47: 029 | E47: Gruppo Proxy Tablet
A48: #VALUE! | B48: VNET_backend-eu-tbl_10-58-41-0 | C48: 10.58.41.0/24 - 255.255.255.0 | D48: 030 | E48: Gruppo Backend Tablet
... A51: #VALUE! | B51: VNET_backend-eu-fe_10-58-61-0 | C51: 10.58.61.0/24 - 255.255.255.0 | D51: 033 | E51: Gruppo Backend Frontend
A52: IAAS - PRODUZIONE NON URGENZA - 10.58.64.0/18
A53: #VALUE! | B53: VNET_vip_10-58-65-0 | C53: 10.58.65.0/24 - 255.255.255.0 | D53: 035 | E53: VIP L4 su edge router
A54: #VALUE! | B54: VNET_monitor_10-58-70-0 | C54: 10.58.70.0/24 - 255.255.255.0 | D54: 040 | E54: Monitoraggio, mail relay
A55: #VALUE! | B55: VNET_sist-tel-neu_10-58-80-0 | C55: 10.58.80.0/24 - 255.255.255.0 | D55: 041 | E55: Sist. Tel. - NEU
A56: #VALUE! | B56: VNET_sist-reg-neu_10-58-85-0 | C56: 10.58.85.0/24 - 255.255.255.0 | D56: 042 | E56: Sist. Reg. - NEU
...

Sheet Integrazioni
B2: WS EROGATI
B3: Integrazione | C3: URL | D3: Cluster - Server Group | E3: Metodo | F3: Note
B4: NUE - schedacontatto | C4: http://172.22.118.10/schedacontatto/NUEServiceBean?wsdl http://eu-sie.ares118.it/schedacontatto/NUEServiceBean | D4: Grp EU - Server g | E4: POST | F4: E' un servizio SOAP che contiene il metodo gestContatto.
B5: GIPSE WEB | C5: https://ext-sie.ares118.it/integrazione-gipse-web/api/v1/fhir/Encounter/{{oid}}/accetta | D5: Grp WS - server ws | E5: POST
C6: https://ext-sie.ares118.it/integrazione-gipse-web/api/v1/fhir/Encounter/{{oid}}/sblocco | D6: Grp WS - server ws | E6: POST
B7: POSTI LETTO | C7: https://ext-sie.ares118.it/pltrasp-ws/PostiLettoService | D7: Grp WS - server ws | E7: POST | F7: E' un servizio SOAP che contiene 3 metodi: listaReparti, modificaDisponibilita, plsie118alive
B8: DAE | C8: https://sie118.ised.it/integrazione-dae/dae/daeclients/listaultimieventi | D8: Grp WS - server ws | E8: POST | F8: non attivo
B12: WS INVOCATI
B13: Progetto | C13: Endpoint Chiamati | D13: Server Group | E13: Metodo | F13: Note | G13: IP
B14: integrazione-dae | C14: https://dae-int.ares118.it/SDODAEServices/rest/authenticationService/authenticateUser | D14: Grp WS - server ws | E14: POST | F14: LINK PER TESTARE SERVIZIO | G14: 10.197.253.16 (IP PSN)
F15: https://sie118.ised.it/integrazione-dae/dae/daeclients/provalogin
F16: https://sie118.ised.it/integrazione-dae/dae/daeclients/letturaevisualizzazione
C17: https://dae-int.ares118.it/SDODAEServices/rest/daeService/getAllDAE
C18: https://dae-int.ares118.it/SDODAEServices/rest/daeService/getAllDAEForMap
C19: https://dae-int.ares118.it/SDODAEServices/rest/daeService/getAllDAEgeoJSON
C20: https://dae-int.ares118.it/SDODAEServices/rest/endpointService/setEndpoints
C21: https://dae-int.ares118.it/SDODAEServices/rest/emergencyService/sendEmergencyEvent
C22: https://dae-int.ares118.it/SDODAEServices/rest/emergencyService/updateEvent
C23: https://dae-int.ares118.it/SDODAEServices/rest/emergencyService/closeEvent
C24: https://dae-int.ares118.it/SDODAEServices/rest/emergencyService/abortEvent
C25: https://dae-int.ares118.it/SDODAEServices/rest/emergencyService/getEventInterventionDetails
B26: integrazione-radio | C26: wss://10.110.7.100:8443/stream?apiKey=<API-KEY> | D26: Grp EU - Server g | G26: 10.110.7.100
C27: https://10.110.7.100:8443/rest/registrar/list?id=<id>&apiKey=<API-KEY> | E27: GET | G27: 10.110.7.100
B28: integrazione-gipse-web | C28: https://gates.regione.lazio.it/gates/fhir/Encounter/ | D28: Grp WS - server ws | E28: POST | G28: 10.7.4.43 ==> 10.13.96.13
C29: https://gates.regione.lazio.it/gates/fhir/Encounter/<id> | E29: DELETE | G29: 10.7.4.43 ==> 10.13.96.13
B30: gipse-integratore (affollamento) | C30: jdbc:oracle:thin:@gipse.sie118.ised.it:1521/poracle01 | D30: Grp EU - Server g | F30: Query sul DB Gipse | G30: 10.2.78.12

Sheet URL-VIP
B1: CLUSTER WILDFLY | C1: VIP | D1: URL
B2: EU (118 + TRAPIANTI) | C2: 10.118.150.25 | D2: https://eu-sie.ares118.it/gui/index.htm
B3: NEU (116117 + PLTRASP) | C3: 10.118.150.26 | D3: https://neu-sie.ares118.it/areariservata/
B4: POSTI LETTO EXT | C4: 10.118.150.27 | D4: https://ext-sie.ares118.it/pltrasp-fe/
B5: MOBILE | C5: 10.118.150.28 | D5: https://mobile-sie.ares118.it/client-mobile/mobileRealTimeTrackMod.jnlp
B6: WEBSERVICES
B7: EROGATORE NUE | C7: 10.118.150.27 | D7: https://ext-sie.ares118.it/pltrasp-ws/PostiLettoService
B8: EROGATORE GIPSE-WEB | D8: https://ext-sie.ares118.it/integrazione-gipse-web/api/v1/fhir/Encounter/{{oid}}/accetta
B9: EROGATORE GIPSE-WEB | D9: https://ext-sie.ares118.it/integrazione-gipse-web/api/v1/fhir/Encounter/{{oid}}/sblocco

Sheet OverviewSubnet
A1: Summary
B3: Label | C3: IP | D3: Hostname | E3: Descrizione | F3: Note | G3: Old_Hostname | H3: OrderNetwork | I3: Seq | J3: Colonna1
B4: Waf Leonardo | C4: 10.197.253.25 | D4: https://eu-sie.ares118.it | E4: 10.58.1.10 (sso-sie,mappe-eu-sie,tunnel-eu-sie) | F4: VIP AS-IS: 10.118.150.25 - Vip Ares 192.168.1.242 | H4: 000 | I4: 1 | J4: =VLOOKUP(OverviewSubnet[[#This Row],[Hostname]],#REF!,2,FALSE) -> #REF!
B5: Waf Leonardo | C5: 10.197.253.26 | D5: https://neu-sie.ares118.it | E5: 10.58.1.11 (tunnel-neu-sie) | F5: VIP AS-IS: 10.118.150.26 - Vip Ares 192.168.1.27 | H5: 000 | I5: 2 | J5: =VLOOKUP(OverviewSubnet[[#This Row],[Hostname]],#REF!,2,FALSE) -> #REF!
B6: Waf Leonardo | C6: 10.197.253.27 | D6: https://ext-sie.ares118.it | E6: 10.58.1.12 | F6: VIP AS-IS: 10.118.150.27 - Vip Ares 192.168.1.28 | H6: 000 | I6: 3 | J6: =VLOOKUP(OverviewSubnet[[#This Row],[Hostname]],#REF!,2,FALSE) -> #REF!
B7: Waf Leonardo | C7: 10.197.253.28 | D7: https://mobile-sie.ares118.it | E7: 10.58.1.13 | F7: VIP AS-IS: 10.118.150.28 - Vip Ares 192.168.1.33 | H7: 000 | I7: 4 | J7: =VLOOKUP(OverviewSubnet[[#This Row],[Hostname]],#REF!,2,FALSE) -> #REF!
B8: Waf Leonardo | C8: 10.197.253.30 | D8: http://172.22.118.10/schedacontatto/NUES… | E8: 10.58.1.10 per NUE 112 | H8: 000 | I8: 5 | J8: =VLOOKUP(OverviewSubnet[[#This Row],[Hostname]],#REF!,2,FALSE) -> #REF!
B9: Waf Leonardo | C9: 10.197.253.32 | D9: https://eu-testsie.ares118.it | E9: 10.58.131.10 (sso-sie,mappe-eu-sie,tunnel-eu-sie) | H9: 000 | I9: 6 | J9: =VLOOKUP(OverviewSubnet[[#This Row],[Hostname]],#REF!,2,FALSE) -> #REF!
B10: Waf Leonardo | C10: 10.197.253.33 | D10: https://neu-testsie.ares118.it | E10: 10.58.131.11 (tunnel-neu-sie) | H10: 000 | I10: 7 | J10: =VLOOKUP(OverviewSubnet[[#This Row],[Hostname]],#REF!,2,FALSE) -> #REF!
B11: Waf Leonardo | C11: 10.197.253.34 | D11: https://ext-testsie.ares118.it | E11: 10.58.131.12 | H11: 000 | I11: 8 | J11: =VLOOKUP(OverviewSubnet[[#This Row],[Hostname]],#REF!,2,FALSE) -> #REF!
B12: Waf Leonardo | C12: 10.197.253.35 | D12: https://mobile-testsie.ares118.it | E12: 10.58.131.13 | H12: 000 | I12: 9 | J12: =VLOOKUP(OverviewSubnet[[#This Row],[Hostname]],#REF!,2,FALSE) -> #REF!
B13: Waf Leonardo | C13: 10.197.253.36 | D13: https://stosie118.ares118.it/gui/index.htm https://stosan-rm.ares118.it/Segreteria/index.faces https://stosan-fr.ares118.it/Segreteria/index.faces https://stosan-lt.ares118.it/Segreteria/index.faces https://stosan-ri.ares118.it/Segreteria/index.faces https://stosan-vt.ares118.it/Segreteria/index.faces https://stolsan-rm.ares118.it/J118BackEndSegreteria/index.do https://stolsan-ri.ares118.it/J118BackEndSegreteria/index.do https://stolsan-fr.ares118.it/J118BackEndSegreteria/index.do https://stolsan-vt.ares118.it/J118BackEndSegreteria/index.do https://stolsan-lt.ares118.it/J118BackEndSegreteria/index.do | E13: - | F13: 10.58.1.23 | H13: 000 | I13: 10 | J13: =VLOOKUP(OverviewSubnet[[#This Row],[Hostname]],#REF!,2,FALSE) -> #VALUE!
B14: Waf Leonardo | C14: 10.197.253.37 | D14: https://bi-sie.ares118.it | H14: 000 | I14: 11 | J14: =VLOOKUP(OverviewSubnet[[#This Row],[Hostname]],#REF!,2,FALSE) -> #REF!
B15: VIP L4 su edge router | C15: 10.58.1.10 | D15: VIP 1 | E15: 10.197.253.25 - eu-sie.ares118.it | H15: 019 | I15: 12 | J15: =VLOOKUP(OverviewSubnet[[#This Row],[Hostname]],#REF!,2,FALSE) -> #REF!
B16: VIP L4 su edge router | C16: 10.58.1.11 | D16: VIP 2 | E16: 10.197.253.26 - neu-sie.ares118.it | H16: 019 | I16: 13 | J16: =VLOOKUP(OverviewSubnet[[#This Row],[Hostname]],#REF!,2,FALSE) -> #REF!
B17: VIP L4 su edge router | C17: 10.58.1.12 | D17: VIP 3 | E17: 10.197.253.27 - ext-sie.ares118.it | H17: 019 | I17: 14 | J17: =VLOOKUP(OverviewSubnet[[#This Row],[Hostname]],#REF!,2,FALSE) -> #REF!
B18: VIP L4 su edge router | C18: 10.58.1.13 | D18: VIP 4 | E18: 10.197.253.28 - mobile-sie.ares118.it | H18: 019 | I18: 15 | J18: =VLOOKUP(OverviewSubnet[[#This Row],[Hostname]],#REF!,2,FALSE) -> #REF!
B19: VIP L4 su edge router | C19: 10.58.1.20 | D19: VIP5 | E19: 10.197.253.36 stosie118.ares118.it (tunnel-stosie118, mappe-stosie118, sso-stosie118) | H19: 019 | I19: 16 | J19: =VLOOKUP(OverviewSubnet[[#This Row],[Hostname]],#REF!,2,FALSE) -> #REF!
B20: VIP L4 su edge router | C20: 10.58.1.21 | D20: VIP6 | E20: 10.197.253.36 stosan-rm.ares118.it (stosan-fr, stosan-lt, stosan-vt, stosan-ri) | H20: 019 | I20: 17 | J20: =VLOOKUP(OverviewSubnet[[#This Row],[Hostname]],#REF!,2,FALSE) -> #REF!
B21: VIP L4 su edge router | C21: 10.58.1.22 | D21: VIP7 | E21: 10.197.253.36 stolsan-rm.ares118.it (stolsan-fr, stolsan-lt, stolsan-vt, stolsan-ri) | H21: 019 | I21: 18 | J21: =VLOOKUP(OverviewSubnet[[#This Row],[Hostname]],#REF!,2,FALSE) -> #REF!
B22: VIP L4 su edge router | C22: 10.58.1.23 | D22: VIP8 | E22: 10.197.253.37 bi-sie.ares118.it | H22: 019 | I22: 19 | J22: =VLOOKUP(OverviewSubnet[[#This Row],[Hostname]],#REF!,2,FALSE) -> #REF!
B23: Ipa, SSO | C23: 10.58.3.4 | D23: bc-prod-ipa01 | E23: SSO di sistema | G23: urg-dc1 | H23: 020 | I23: 20 | J23: =VLOOKUP(OverviewSubnet[[#This Row],[Hostname]],#REF!,2,FALSE) -> #REF!
B24: Ipa, SSO | C24: 10.58.3.5 | D24: bc-prod-ipa02 | E24: SSO di sistema | G24: urg-dc2 | H24: 020 | I24: 21 | J24: =VLOOKUP(OverviewSubnet[[#This Row],[Hostname]],#REF!,2,FALSE) -> #REF!
B25: Ipa, SSO | C25: 10.58.3.6 | D25: urg-dns1 | E25: DNS INTERNO | F25: DA RINOMINARE IN - bc-prod-dns-01 | G25: urg-dns1 | H25: 020 | I25: 22 | J25: =VLOOKUP(OverviewSubnet[[#This Row],[Hostname]],#REF!,2,FALSE) -> #REF!
B26: Ipa, SSO | C26: 10.58.3.7 | D26: urg-dns2 | E26: DNS INTERNO | F26: DA RINOMINARE IN - bc-prod-dns-02 | G26: urg-dns2 | H26: 020 | I26: 23 | J26: =VLOOKUP(OverviewSubnet[[#This Row],[Hostname]],#REF!,2,FALSE) -> #REF!
B27: Ipa, SSO | C27: 10.58.3.252 | D27: fwd-proxy | E27: Forward Proxy | H27: 020 | I27: 24 | J27: =VLOOKUP(OverviewSubnet[[#This Row],[Hostname]],#REF!,2,FALSE) -> #REF!
B28: Ipa, SSO | C28: 10.58.3.253 | D28: kickstart-ca | E28: Reverse Proxy (Nginx KickStart) | H28: 020 | I28: 25 | J28: =VLOOKUP(OverviewSubnet[[#This Row],[Hostname]],#REF!,2,FALSE) -> #REF!
B29: Gruppo AD - LDAP / GPO PDL e TABLET - DHCP PDL | C29: 10.58.4.11 | D29: bc-p-app-ad1 | E29: Active Directory Applicazione - LDAP | F29: Windows server 2022 | G29: prod-urg-appad1 GIA' bc-prod-app-ad01 | H29: 021 | I29: 26 | J29: =VLOOKUP(OverviewSubnet[[#This Row],[Hostname]],#REF!,2,FALSE) -> #REF!
B30: Gruppo AD - LDAP / GPO PDL e TABLET - DHCP PDL | C30: 10.58.4.12 | D30: bc-p-app-ad2 | E30: Active Directory Applicazione - LDAP | F30: Windows server 2022 | G30: prod-urg-appad2 GIA' bc-prod-app-ad02 | H30: 021 | I30: 27 | J30: =VLOOKUP(OverviewSubnet[[#This Row],[Hostname]],#REF!,2,FALSE) -> #REF!
B31: Gruppo AD - LDAP / GPO PDL e TABLET - DHCP PDL | C31: 10.58.4.21 | D31: #bc-prod-dhcp01 | E31: #DHCP Client PDL | H31: 021 | I31: 28 | J31: =VLOOKUP(OverviewSubnet[[#This Row],[Hostname]],#REF!,2,FALSE) -> #REF!
B32: Gruppo AD - LDAP / GPO PDL e TABLET - DHCP PDL | C32: 10.58.4.31 | D32: #bc-p-dcpdl1 | E32: #Dominio/GPO PDL + DNS | F32: Windows server 2022 | G32: bc-prod-dcpdl01 | H32: 021 | I32: 29 | J32: =VLOOKUP(OverviewSubnet[[#This Row],[Hostname]],#REF!,2,FALSE) -> #REF!
B33: Gruppo AD - LDAP / GPO PDL e TABLET - DHCP PDL | C33: 10.58.4.32 | D33: #bc-p-dcpdl2 | E33: #Dominio/GPO PDL + DNS | F33: Windows server 2022 | G33: bc-prod-dcpdl02 | H33: 021 | I33: 30 | J33: =VLOOKUP(OverviewSubnet[[#This Row],[Hostname]],#REF!,2,FALSE) -> #REF!
B34: Monitoraggio, mail relay | C34: 10.58.10.4 | D34: test-psn-ping | E34: Macchina di test in gestione PSN | F34: VM-PSN | H34: 022 | I34: 31 | J34: =VLOOKUP(OverviewSubnet[[#This Row],[Hostname]],#REF!,2,FALSE) -> #REF!
B35: Monitoraggio, mail relay | C35: 10.58.10.5 | D35: bc-prod-chk01 | E35: Sistema di monitoraggio | F35: Check MK | G35: urg-checkmk1 | H35: 022 | I35: 32 | J35: =VLOOKUP(OverviewSubnet[[#This Row],[Hostname]],#REF!,2,FALSE) -> #REF!
B36: Monitoraggio, mail relay | C36: 10.58.10.6 | D36: bc-prod-kib01 | E36: Sistema di monitoraggio | F36: Kibana | G36: urg-kib1 | H36: 022 | I36: 33 | J36: =VLOOKUP(OverviewSubnet[[#This Row],[Hostname]],#REF!,2,FALSE) -> #REF!
B37: Monitoraggio, mail relay | C37: 10.58.10.21 | D37: bc-prod-mail01 | E37: Mail Relay per consegna posta | F37: Mail Relay | H37: 022 | I37: 34 | J37: =VLOOKUP(OverviewSubnet[[#This Row],[Hostname]],#REF!,2,FALSE) -> #REF!
B38: Monitoraggio, mail relay | C38: 10.58.10.31 | D38: #bc-prod-nagios01 | E38: #Sistema di monitoraggio | F38: Nagios | H38: 022 | I38: 35 | J38: =VLOOKUP(OverviewSubnet[[#This Row],[Hostname]],#REF!,2,FALSE) -> #REF!
B39: Monitoraggio, mail relay | C39: 10.58.10.91 | D39: bc-prod-elx01 | E39: Sistema di monitoraggio | F39: Elastik Search | G39: urg-elk1 | H39: 022 | I39: 36 | J39: =VLOOKUP(OverviewSubnet[[#This Row],[Hostname]],#REF!,2,FALSE) -> #REF!
B40: Monitoraggio, mail relay | C40: 10.58.10.92 | D40: bc-prod-elx02 | E40: Sistema di monitoraggio | F40: Elastik Search | G40: urg-elk2 | H40: 022 | I40: 37 | J40: =VLOOKUP(OverviewSubnet[[#This Row],[Hostname]],#REF!,2,FALSE) -> #REF!
B41: Monitoraggio, mail relay | C41: 10.58.10.93 | D41: bc-prod-elx03 | E41: Sistema di monitoraggio | F41: Elastik Search | G41: urg-elk3 | H41: 022 | I41: 38 | J41: =VLOOKUP(OverviewSubnet[[#This Row],[Hostname]],#REF!,2,FALSE) -> #REF!
...

Sheet DC Acilia Housing Dati
A1: Summary | D1: ID: | E1: =Summary!D5 -> 001 | F1: 5
B2: {=MID(CELL("nomefile",A1),FIND("]",CELL("nomefile",A1))+1,255)} -> #VALUE! | D2: Label: | E2: =Summary!B5 -> DC Acilia Housing Dati
B4: Label | C4: ID | D4: IP | E4: hostname | F4: Descrizione | G4: NOTE
B5: =$E$2 -> DC Acilia Housing Dati | C5: =$E$1 -> 001 | D5: 192.168.210.0 | F5: =VLOOKUP(B2,Summary!B4:E123,2,FALSE) -> #VALUE!
B6: =$E$2 -> DC Acilia Housing Dati | C6: =$E$1 -> 001 | D6: 192.168.210.1 | F6: gateway
B7: =$E$2 -> DC Acilia Housing Dati | C7: =$E$1 -> 001 | D7: 192.168.210.2
B8: =$E$2 -> DC Acilia Housing Dati | C8: =$E$1 -> 001 | D8: 192.168.210.3
B9: =$E$2 -> DC Acilia Housing Dati | C9: =$E$1 -> 001 | D9: 192.168.210.4
B10: =$E$2 -> DC Acilia Housing Dati | C10: =$E$1 -> 001 | D10: 192.168.210.5
B11: =$E$2 -> DC Acilia Housing Dati | C11: =$E$1 -> 001 | D11: 192.168.210.6
B12: =$E$2 -> DC Acilia Housing Dati | C12: =$E$1 -> 001 | D12: 192.168.210.7
B13: =$E$2 -> DC Acilia Housing Dati | C13: =$E$1 -> 001 | D13: 192.168.210.8
B14: =$E$2 -> DC Acilia Housing Dati | C14: =$E$1 -> 001 | D14: 192.168.210.9
B15: =$E$2 -> DC Acilia Housing Dati | C15: =$E$1 -> 001 | D15: 192.168.210.10 | E15: ac-urg-rec-tdm1 | F15: Recorder EMERGENZA/URGENZA sito ACILIA | G15: LACP 2 porte per NEC (uno per ciascuno switch)
B16: =$E$2 -> DC Acilia Housing Dati | C16: =$E$1 -> 001 | D16: 192.168.210.11
B17: =$E$2 -> DC Acilia Housing Dati | C17: =$E$1 -> 001 | D17: 192.168.210.12
B18: =$E$2 -> DC Acilia Housing Dati | C18: =$E$1 -> 001 | D18: 192.168.210.13
B19: =$E$2 -> DC Acilia Housing Dati | C19: =$E$1 -> 001 | D19: 192.168.210.14
B20: =$E$2 -> DC Acilia Housing Dati | C20: =$E$1 -> 001 | D20: 192.168.210.15
B21: =$E$2 -> DC Acilia Housing Dati | C21: =$E$1 -> 001 | D21: 192.168.210.16
B22: =$E$2 -> DC Acilia Housing Dati | C22: =$E$1 -> 001 | D22: 192.168.210.17
B23: =$E$2 -> DC Acilia Housing Dati | C23: =$E$1 -> 001 | D23: 192.168.210.18
B24: =$E$2 -> DC Acilia Housing Dati | C24: =$E$1 -> 001 | D24: 192.168.210.19
B25: =$E$2 -> DC Acilia Housing Dati | C25: =$E$1 -> 001 | D25: 192.168.210.20 | E25: ac-neu-rec-tdm1 | F25: Recorder ORDINARIO sito ACILIA | G25: LACP 2 porte per NEC (uno per ciascuno switch)
B26: =$E$2 -> DC Acilia Housing Dati | C26: =$E$1 -> 001 | D26: 192.168.210.21
B27: =$E$2 -> DC Acilia Housing Dati | C27: =$E$1 -> 001 | D27: 192.168.210.22
B28: =$E$2 -> DC Acilia Housing Dati | C28: =$E$1 -> 001 | D28: 192.168.210.23
B29: =$E$2 -> DC Acilia Housing Dati | C29: =$E$1 -> 001 | D29: 192.168.210.24
B30: =$E$2 -> DC Acilia Housing Dati | C30: =$E$1 -> 001 | D30: 192.168.210.25
B31: =$E$2 -> DC Acilia Housing Dati | C31: =$E$1 -> 001 | D31: 192.168.210.26
B32: =$E$2 -> DC Acilia Housing Dati | C32: =$E$1 -> 001 | D32: 192.168.210.27
B33: =$E$2 -> DC Acilia Housing Dati | C33: =$E$1 -> 001 | D33: 192.168.210.28
B34: =$E$2 -> DC Acilia Housing Dati | C34: =$E$1 -> 001 | D34: 192.168.210.29
B35: =$E$2 -> DC Acilia Housing Dati | C35: =$E$1 -> 001 | D35: 192.168.210.30
B36: =$E$2 -> DC Acilia Housing Dati | C36: =$E$1 -> 001 | D36: 192.168.210.31
B37: =$E$2 -> DC Acilia Housing Dati | C37: =$E$1 -> 001 | D37: 192.168.210.32
... B131: =$E$2 -> DC Acilia Housing Dati | C131: =$E$1 -> 001 | D131: 192.168.210.126
B132: =$E$2 -> DC Acilia Housing Dati | C132: =$E$1 -> 001 | D132: 192.168.210.127 | F132: broadcast

Sheet DC Acilia Housing VoIP
A1: Summary | D1: ID: | E1: =Summary!D6 -> 002 | F1: ='DC Acilia Housing Dati'!F1+1 -> 6
B2: {=MID(CELL("nomefile",A1),FIND("]",CELL("nomefile",A1))+1,255)} -> #VALUE! | D2: Label: | E2: =Summary!B6 -> DC Acilia Housing Voip
B4: Label | C4: ID | D4: IP | E4: hostname | F4: Descrizione | G4: NOTE | H4: OLD_hostname | I4: eu
B5: =$E$2 -> DC Acilia Housing Voip | C5: =$E$1 -> 002 | D5: 192.168.210.128 | F5: =VLOOKUP(B2,Summary!B4:E123,2,FALSE) -> #VALUE! | I5: 2 | J5: per i 2 switch
B6: =$E$2 -> DC Acilia Housing Voip | C6: =$E$1 -> 002 | D6: 192.168.210.129 | F6: gateway | I6: 2 | J6: per le due asu -snx/snridx)
B7: =$E$2 -> DC Acilia Housing Voip | C7: =$E$1 -> 002 | D7: 192.168.210.130 | E7: ac-urg-tel-vipsn1 | F7: VIP /alias SN1 del sito Acilia dedicato all'EMERGENZA/URGENZA | I7: 1 | J7: alias per snx/snridx
B8: =$E$2 -> DC Acilia Housing Voip | C8: =$E$1 -> 002 | D8: 192.168.210.131 | E8: ac-urg-tel-prmsn1 | F8: Service Node 1 Primario - EMERGENZA/URGENZA | I8: 2 | J8: per il db cassandra
B9: =$E$2 -> DC Acilia Housing Voip | C9: =$E$1 -> 002 | D9: 192.168.210.132 | E9: ac-urg-tel-ridsn1 | F9: Service Node 1 Ridondanza - EMERGENZA/URGENZA | I9: 6 | J9: per le 3 mgu (2 x mgu)
B10: =$E$2 -> DC Acilia Housing Voip | C10: =$E$1 -> 002 | D10: 192.168.210.133 | F10: DB Cassandra Primario - EMERGENZA/URGENZA | I10: =SUM(I5:I9) -> 13
B11: =$E$2 -> DC Acilia Housing Voip | C11: =$E$1 -> 002 | D11: 192.168.210.134 | F11: DB Cassandra Ridondanza - EMERGENZA/URGENZA
B12: =$E$2 -> DC Acilia Housing Voip | C12: =$E$1 -> 002 | D12: 192.168.210.135 | I12: neu
B13: =$E$2 -> DC Acilia Housing Voip | C13: =$E$1 -> 002 | D13: 192.168.210.136 | I13: 2 | J13: per i 2 switch
B14: =$E$2 -> DC Acilia Housing Voip | C14: =$E$1 -> 002 | D14: 192.168.210.137 | I14: 2 | J14: per le due asu -snx/snridx)
B15: =$E$2 -> DC Acilia Housing Voip | C15: =$E$1 -> 002 | D15: 192.168.210.138 | I15: 1 | J15: alias per snx/snridx
B16: =$E$2 -> DC Acilia Housing Voip | C16: =$E$1 -> 002 | D16: 192.168.210.139 | I16: 2 | J16: per il db cassandra
B17: =$E$2 -> DC Acilia Housing Voip | C17: =$E$1 -> 002 | D17: 192.168.210.140 | I17: 4 | J17: per le 2 mgu (2 x mgu)
B18: =$E$2 -> DC Acilia Housing Voip | C18: =$E$1 -> 002 | D18: 192.168.210.141 | F18: Media Gateway MGU 1 - EMERGENZA/URGENZA - Controller | I18: =SUM(I13:I17) -> 11
B19: =$E$2 -> DC Acilia Housing Voip | C19: =$E$1 -> 002 | D19: 192.168.210.142 | F19: Media Gateway MGU 1 - EMERGENZA/URGENZA - RTP Resources
B20: =$E$2 -> DC Acilia Housing Voip | C20: =$E$1 -> 002 | D20: 192.168.210.143 | F20: Media Gateway MGU 2 - EMERGENZA/URGENZA | I20: =+I10+I18 -> 24
B21: =$E$2 -> DC Acilia Housing Voip | C21: =$E$1 -> 002 | D21: 192.168.210.144 | F21: Media Gateway MGU 2 - EMERGENZA/URGENZA
B22: =$E$2 -> DC Acilia Housing Voip | C22: =$E$1 -> 002 | D22: 192.168.210.145 | F22: Media Gateway MGU 3 - EMERGENZA/URGENZA
B23: =$E$2 -> DC Acilia Housing Voip | C23: =$E$1 -> 002 | D23: 192.168.210.146 | F23: Media Gateway MGU 3 - EMERGENZA/URGENZA
B24: =$E$2 -> DC Acilia Housing Voip | C24: =$E$1 -> 002 | D24: 192.168.210.147
B25: =$E$2 -> DC Acilia Housing Voip | C25: =$E$1 -> 002 | D25: 192.168.210.148 | J25: ac-prod-urg-tel-prmsn1
B26: =$E$2 -> DC Acilia Housing Voip | C26: =$E$1 -> 002 | D26: 192.168.210.149
B27: =$E$2 -> DC Acilia Housing Voip | C27: =$E$1 -> 002 | D27: 192.168.210.150
B28: =$E$2 -> DC Acilia Housing Voip | C28: =$E$1 -> 002 | D28: 192.168.210.151 | E28: ac-urg-tel-sw1 | F28: Switch dedicato al SN1 - EMERGENZA/URGENZA
B29: =$E$2 -> DC Acilia Housing Voip | C29: =$E$1 -> 002 | D29: 192.168.210.152 | E29: ac-urg-tel-sw2 | F29: Switch dedicato al SN1 - EMERGENZA/URGENZA
B30: =$E$2 -> DC Acilia Housing Voip | C30: =$E$1 -> 002 | D30: 192.168.210.153 | J30: ac-prod-urg-rec-evoip1
B31: =$E$2 -> DC Acilia Housing Voip | C31: =$E$1 -> 002 | D31: 192.168.210.154 | J31: ac-prod-urg-rec-dbevoip1
B32: =$E$2 -> DC Acilia Housing Voip | C32: =$E$1 -> 002 | D32: 192.168.210.155
B33: =$E$2 -> DC Acilia Housing Voip | C33: =$E$1 -> 002 | D33: 192.168.210.156
B34: =$E$2 -> DC Acilia Housing Voip | C34: =$E$1 -> 002 | D34: 192.168.210.157
B35: =$E$2 -> DC Acilia Housing Voip | C35: =$E$1 -> 002 | D35: 192.168.210.158
B36: =$E$2 -> DC Acilia Housing Voip | C36: =$E$1 -> 002 | D36: 192.168.210.159
B37: =$E$2 -> DC Acilia Housing Voip | C37: =$E$1 -> 002 | D37: 192.168.210.160 | E37: ac-neu-tel-vipsn1 | F37: VIP /alias SN1 del sito Acilia dedicato alla NON URGENZA
B38: =$E$2 -> DC Acilia Housing Voip | C38: =$E$1 -> 002 | D38: 192.168.210.161 | E38: ac-neu-tel-prmsn1 | F38: Service Node 1 Primario - NON URGENZA
B39: =$E$2 -> DC Acilia Housing Voip | C39: =$E$1 -> 002 | D39: 192.168.210.162 | E39: ac-neu-tel-ridsn1 | F39: Service Node 1 Ridondanza - NON URGENZA
B40: =$E$2 -> DC Acilia Housing Voip | C40: =$E$1 -> 002 | D40: 192.168.210.163 | F40: DB Cassandra Primario - NON URGENZA
B41: =$E$2 -> DC Acilia Housing Voip | C41: =$E$1 -> 002 | D41: 192.168.210.164 | F41: DB Cassandra Ridondanza - NON URGENZA
...

Sheet DC Acilia Housing Mng
A1: Summary | D1: ID: | E1: =Summary!D7 -> 003 | F1: ='DC Acilia Housing Dati'!F1+1 -> 6
B2: {=MID(CELL("nomefile",A1),FIND("]",CELL("nomefile",A1))+1,255)} -> #VALUE! | D2: Label: | E2: =Summary!B7 -> DC Acilia Housing Mng
B4: Label | C4: ID | D4: IP | E4: hostname | F4: Descrizione | G4: Note | H4: OLD_hostname
B5: =$E$2 -> DC Acilia Housing Mng | C5: =$E$1 -> 003 | D5: 192.168.241.0 | F5: =VLOOKUP(B2,Summary!B4:E123,2,FALSE) -> #VALUE! | J5: 32
B6: =$E$2 -> DC Acilia Housing Mng | C6: =$E$1 -> 003 | D6: 192.168.241.1 | J6: 33
B7: =$E$2 -> DC Acilia Housing Mng | C7: =$E$1 -> 003 | D7: 192.168.241.2 | F7: switch N&C | J7: 34
B8: =$E$2 -> DC Acilia Housing Mng | C8: =$E$1 -> 003 | D8: 192.168.241.3 | F8: switch N&C | J8: 35
B9: =$E$2 -> DC Acilia Housing Mng | C9: =$E$1 -> 003 | D9: 192.168.241.4 | J9: 36
B10: =$E$2 -> DC Acilia Housing Mng | C10: =$E$1 -> 003 | D10: 192.168.241.5 | J10: 37
B11: =$E$2 -> DC Acilia Housing Mng | C11: =$E$1 -> 003 | D11: 192.168.241.6 | J11: 38
B12: =$E$2 -> DC Acilia Housing Mng | C12: =$E$1 -> 003 | D12: 192.168.241.7 | J12: 39
B13: =$E$2 -> DC Acilia Housing Mng | C13: =$E$1 -> 003 | D13: 192.168.241.8 | J13: 40
B14: =$E$2 -> DC Acilia Housing Mng | C14: =$E$1 -> 003 | D14: 192.168.241.9 | J14: 41
B15: =$E$2 -> DC Acilia Housing Mng | C15: =$E$1 -> 003 | D15: 192.168.241.10 | F15: switch URG #1 Acilia | J15: 42
B16: =$E$2 -> DC Acilia Housing Mng | C16: =$E$1 -> 003 | D16: 192.168.241.11 | F16: switch URG #2 Acilia | J16: 43
B17: =$E$2 -> DC Acilia Housing Mng | C17: =$E$1 -> 003 | D17: 192.168.241.12 | J17: 44
B18: =$E$2 -> DC Acilia Housing Mng | C18: =$E$1 -> 003 | D18: 192.168.241.13 | J18: 45
B19: =$E$2 -> DC Acilia Housing Mng | C19: =$E$1 -> 003 | D19: 192.168.241.14 | J19: 46
B20: =$E$2 -> DC Acilia Housing Mng | C20: =$E$1 -> 003 | D20: 192.168.241.15 | J20: 47
B21: =$E$2 -> DC Acilia Housing Mng | C21: =$E$1 -> 003 | D21: 192.168.241.16 | J21: 48
B22: =$E$2 -> DC Acilia Housing Mng | C22: =$E$1 -> 003 | D22: 192.168.241.17 | J22: 49
B23: =$E$2 -> DC Acilia Housing Mng | C23: =$E$1 -> 003 | D23: 192.168.241.18 | J23: 50
B24: =$E$2 -> DC Acilia Housing Mng | C24: =$E$1 -> 003 | D24: 192.168.241.19 | J24: 51
B25: =$E$2 -> DC Acilia Housing Mng | C25: =$E$1 -> 003 | D25: 192.168.241.20 | J25: 52
B26: =$E$2 -> DC Acilia Housing Mng | C26: =$E$1 -> 003 | D26: 192.168.241.21 | J26: 53
B27: =$E$2 -> DC Acilia Housing Mng | C27: =$E$1 -> 003 | D27: 192.168.241.22 | J27: 54
B28: =$E$2 -> DC Acilia Housing Mng | C28: =$E$1 -> 003 | D28: 192.168.241.23 | J28: 55
... B35: =$E$2 -> DC Acilia Housing Mng | C35: =$E$1 -> 003 | D35: 192.168.241.30 | J35: 62
B36: =$E$2 -> DC Acilia Housing Mng | C36: =$E$1 -> 003 | D36: 192.168.241.31 | F36: broadcast | J36: 63

Sheet DC Pomezia Housing Dati
A1: Summary | D1: ID: | E1: =Summary!D8 -> 004 | F1: ='DC Acilia Housing Dati'!F1+1 -> 6
B2: {=MID(CELL("nomefile",A1),FIND("]",CELL("nomefile",A1))+1,255)} -> #VALUE! | D2: Label: | E2: =Summary!B8 -> DC Pomezia Housing Dati
B4: Label | C4: ID | D4: IP | E4: hostname | F4: Descrizione | G4: Note | H4: OLD_hostname
B5: =$E$2 -> DC Pomezia Housing Dati | C5: =$E$1 -> 004 | D5: 192.168.220.0 | F5: =VLOOKUP(B2,Summary!B4:E123,2,FALSE) -> #VALUE!
B6: =$E$2 -> DC Pomezia Housing Dati | C6: =$E$1 -> 004 | D6: 192.168.220.1 | F6: gateway
B7: =$E$2 -> DC Pomezia Housing Dati | C7: =$E$1 -> 004 | D7: 192.168.220.2
B8: =$E$2 -> DC Pomezia Housing Dati | C8: =$E$1 -> 004 | D8: 192.168.220.3
B9: =$E$2 -> DC Pomezia Housing Dati | C9: =$E$1 -> 004 | D9: 192.168.220.4
B10: =$E$2 -> DC Pomezia Housing Dati | C10: =$E$1 -> 004 | D10: 192.168.220.5
B11: =$E$2 -> DC Pomezia Housing Dati | C11: =$E$1 -> 004 | D11: 192.168.220.6
B12: =$E$2 -> DC Pomezia Housing Dati | C12: =$E$1 -> 004 | D12: 192.168.220.7
B13: =$E$2 -> DC Pomezia Housing Dati | C13: =$E$1 -> 004 | D13: 192.168.220.8
B14: =$E$2 -> DC Pomezia Housing Dati | C14: =$E$1 -> 004 | D14: 192.168.220.9
B15: =$E$2 -> DC Pomezia Housing Dati | C15: =$E$1 -> 004 | D15: 192.168.220.10 | E15: pm-urg-rec-tdm2 | F15: Recorder EMERGENZA/URGENZA sito POMEZIA | G15: LACP 2 porte per NEC (uno per ciascuno switch)
B16: =$E$2 -> DC Pomezia Housing Dati | C16: =$E$1 -> 004 | D16: 192.168.220.11
B17: =$E$2 -> DC Pomezia Housing Dati | C17: =$E$1 -> 004 | D17: 192.168.220.12
B18: =$E$2 -> DC Pomezia Housing Dati | C18: =$E$1 -> 004 | D18: 192.168.220.13
B19: =$E$2 -> DC Pomezia Housing Dati | C19: =$E$1 -> 004 | D19: 192.168.220.14
B20: =$E$2 -> DC Pomezia Housing Dati | C20: =$E$1 -> 004 | D20: 192.168.220.15
B21: =$E$2 -> DC Pomezia Housing Dati | C21: =$E$1 -> 004 | D21: 192.168.220.16
B22: =$E$2 -> DC Pomezia Housing Dati | C22: =$E$1 -> 004 | D22: 192.168.220.17
B23: =$E$2 -> DC Pomezia Housing Dati | C23: =$E$1 -> 004 | D23: 192.168.220.18
B24: =$E$2 -> DC Pomezia Housing Dati | C24: =$E$1 -> 004 | D24: 192.168.220.19
B25: =$E$2 -> DC Pomezia Housing Dati | C25: =$E$1 -> 004 | D25: 192.168.220.20 | E25: pm-neu-rec-tdm2 | F25: Recorder NON Emergenza/Urgenza sito POMEZIA | G25: LACP 2 porte per NEC (uno per ciascuno switch)
B26: =$E$2 -> DC Pomezia Housing Dati | C26: =$E$1 -> 004 | D26: 192.168.220.21
B27: =$E$2 -> DC Pomezia Housing Dati | C27: =$E$1 -> 004 | D27: 192.168.220.22
B28: =$E$2 -> DC Pomezia Housing Dati | C28: =$E$1 -> 004 | D28: 192.168.220.23
B29: =$E$2 -> DC Pomezia Housing Dati | C29: =$E$1 -> 004 | D29: 192.168.220.24
B30: =$E$2 -> DC Pomezia Housing Dati | C30: =$E$1 -> 004 | D30: 192.168.220.25
B31: =$E$2 -> DC Pomezia Housing Dati | C31: =$E$1 -> 004 | D31: 192.168.220.26
B32: =$E$2 -> DC Pomezia Housing Dati | C32: =$E$1 -> 004 | D32: 192.168.220.27
B33: =$E$2 -> DC Pomezia Housing Dati | C33: =$E$1 -> 004 | D33: 192.168.220.28
B34: =$E$2 -> DC Pomezia Housing Dati | C34: =$E$1 -> 004 | D34: 192.168.220.29
B35: =$E$2 -> DC Pomezia Housing Dati | C35: =$E$1 -> 004 | D35: 192.168.220.30
B36: =$E$2 -> DC Pomezia Housing Dati | C36: =$E$1 -> 004 | D36: 192.168.220.31
B37: =$E$2 -> DC Pomezia Housing Dati | C37: =$E$1 -> 004 | D37: 192.168.220.32
... B131: =$E$2 -> DC Pomezia Housing Dati | C131: =$E$1 -> 004 | D131: 192.168.220.126
B132: =$E$2 -> DC Pomezia Housing Dati | C132: =$E$1 -> 004 | D132: 192.168.220.127 | F132: broadcast

Sheet DC Pomezia Housing Voip
A1: Summary | D1: ID: | E1: =Summary!D9 -> 005 | F1: ='DC Acilia Housing Dati'!F1+1 -> 6
B2: {=MID(CELL("nomefile",A1),FIND("]",CELL("nomefile",A1))+1,255)} -> #VALUE! | D2: Label: | E2: =Summary!B9 -> DC Pomezia Housing Voip
B4: Label | C4: ID | D4: IP | E4: hostname | F4: Descrizione | G4: Note | H4: OLD_hostname
B5: =$E$2 -> DC Pomezia Housing Voip | C5: =$E$1 -> 005 | D5: 192.168.220.128 | F5: =VLOOKUP(B2,Summary!B4:E123,2,FALSE) -> #VALUE!
B6: =$E$2 -> DC Pomezia Housing Voip | C6: =$E$1 -> 005 | D6: 192.168.220.129 | F6: gateway
B7: =$E$2 -> DC Pomezia Housing Voip | C7: =$E$1 -> 005 | D7: 192.168.220.130 | E7: pm-urg-tel-vipsn1 | F7: VIP /alias SN1 del sito Pomezia dedicato all'EMERGENZA/URGENZA
B8: =$E$2 -> DC Pomezia Housing Voip | C8: =$E$1 -> 005 | D8: 192.168.220.131 | E8: pm-urg-tel-prmsn1 | F8: Service Node 1 Primario - EMERGENZA/URGENZA
B9: =$E$2 -> DC Pomezia Housing Voip | C9: =$E$1 -> 005 | D9: 192.168.220.132 | E9: pm-urg-tel-ridsn1 | F9: Service Node 1 Ridondanza - EMERGENZA/URGENZA
B10: =$E$2 -> DC Pomezia Housing Voip | C10: =$E$1 -> 005 | D10: 192.168.220.133 | F10: DB Cassandra Primario - EMERGENZA/URGENZA
B11: =$E$2 -> DC Pomezia Housing Voip | C11: =$E$1 -> 005 | D11: 192.168.220.134 | F11: DB Cassandra Ridondanza - EMERGENZA/URGENZA
B12: =$E$2 -> DC Pomezia Housing Voip | C12: =$E$1 -> 005 | D12: 192.168.220.135
B13: =$E$2 -> DC Pomezia Housing Voip | C13: =$E$1 -> 005 | D13: 192.168.220.136
B14: =$E$2 -> DC Pomezia Housing Voip | C14: =$E$1 -> 005 | D14: 192.168.220.137
B15: =$E$2 -> DC Pomezia Housing Voip | C15: =$E$1 -> 005 | D15: 192.168.220.138
B16: =$E$2 -> DC Pomezia Housing Voip | C16: =$E$1 -> 005 | D16: 192.168.220.139
B17: =$E$2 -> DC Pomezia Housing Voip | C17: =$E$1 -> 005 | D17: 192.168.220.140
B18: =$E$2 -> DC Pomezia Housing Voip | C18: =$E$1 -> 005 | D18: 192.168.220.141 | F18: Media Gateway MGU 1 - EMERGENZA/URGENZA
B19: =$E$2 -> DC Pomezia Housing Voip | C19: =$E$1 -> 005 | D19: 192.168.220.142 | F19: Media Gateway MGU 1 - EMERGENZA/URGENZA
B20: =$E$2 -> DC Pomezia Housing Voip | C20: =$E$1 -> 005 | D20: 192.168.220.143 | F20: Media Gateway MGU 2 - EMERGENZA/URGENZA
B21: =$E$2 -> DC Pomezia Housing Voip | C21: =$E$1 -> 005 | D21: 192.168.220.144 | F21: Media Gateway MGU 2 - EMERGENZA/URGENZA
B22: =$E$2 -> DC Pomezia Housing Voip | C22: =$E$1 -> 005 | D22: 192.168.220.145 | F22: Media Gateway MGU 3 - EMERGENZA/URGENZA
B23: =$E$2 -> DC Pomezia Housing Voip | C23: =$E$1 -> 005 | D23: 192.168.220.146 | F23: Media Gateway MGU 3 - EMERGENZA/URGENZA
B24: =$E$2 -> DC Pomezia Housing Voip | C24: =$E$1 -> 005 | D24: 192.168.220.147
B25: =$E$2 -> DC Pomezia Housing Voip | C25: =$E$1 -> 005 | D25: 192.168.220.148
B26: =$E$2 -> DC Pomezia Housing Voip | C26: =$E$1 -> 005 | D26: 192.168.220.149
B27: =$E$2 -> DC Pomezia Housing Voip | C27: =$E$1 -> 005 | D27: 192.168.220.150
B28: =$E$2 -> DC Pomezia Housing Voip | C28: =$E$1 -> 005 | D28: 192.168.220.151 | E28: pm-urg-tel-sw1 | F28: Switch dedicato al SN1 - EMERGENZA/URGENZA
B29: =$E$2 -> DC Pomezia Housing Voip | C29: =$E$1 -> 005 | D29: 192.168.220.152 | E29: pm-urg-tel-sw2 | F29: Switch dedicato al SN1 - EMERGENZA/URGENZA
B30: =$E$2 -> DC Pomezia Housing Voip | C30: =$E$1 -> 005 | D30: 192.168.220.153
B31: =$E$2 -> DC Pomezia Housing Voip | C31: =$E$1 -> 005 | D31: 192.168.220.154
B32: =$E$2 -> DC Pomezia Housing Voip | C32: =$E$1 -> 005 | D32: 192.168.220.155
B33: =$E$2 -> DC Pomezia Housing Voip | C33: =$E$1 -> 005 | D33: 192.168.220.156
B34: =$E$2 -> DC Pomezia Housing Voip | C34: =$E$1 -> 005 | D34: 192.168.220.157
B35: =$E$2 -> DC Pomezia Housing Voip | C35: =$E$1 -> 005 | D35: 192.168.220.158
B36: =$E$2 -> DC Pomezia Housing Voip | C36: =$E$1 -> 005 | D36: 192.168.220.159
B37: =$E$2 -> DC Pomezia Housing Voip | C37: =$E$1 -> 005 | D37: 192.168.220.160 | E37: pm-neu-tel-vipsn1 | F37: VIP /alias SN1 del sito Pomezia dedicato alla NON URGENZA
B38: =$E$2 -> DC Pomezia Housing Voip | C38: =$E$1 -> 005 | D38: 192.168.220.161 | E38: pm-neu-tel-prmsn1 | F38: Service Node 1 Primario - NON URGENZA
B39: =$E$2 -> DC Pomezia Housing Voip | C39: =$E$1 -> 005 | D39: 192.168.220.162 | E39: pm-neu-tel-ridsn1 | F39: Service Node 1 Ridondanza - NON URGENZA
B40: =$E$2 -> DC Pomezia Housing Voip | C40: =$E$1 -> 005 | D40: 192.168.220.163 | F40: DB Cassandra Primario - NON URGENZA
B41: =$E$2 -> DC Pomezia Housing Voip | C41: =$E$1 -> 005 | D41: 192.168.220.164 | F41: DB Cassandra Ridondanza - NON URGENZA
...

Sheet DC Pomezia Housing Mng
A1: Summary | D1: ID: | E1: =Summary!D10 -> 006 | F1: ='DC Acilia Housing Dati'!F1+1 -> 6
B2: {=MID(CELL("nomefile",A1),FIND("]",CELL("nomefile",A1))+1,255)} -> #VALUE! | D2: Label: | E2: =Summary!B10 -> DC Pomezia Housing Mng
B4: Label | C4: ID | D4: IP | E4: hostname | F4: Descrizione | G4: Note | H4: OLD_hostname
B5: =$E$2 -> DC Pomezia Housing Mng | C5: =$E$1 -> 006 | D5: 192.168.241.32 | F5: =VLOOKUP(B2,Summary!B4:E123,2,FALSE) -> #VALUE!
B6: =$E$2 -> DC Pomezia Housing Mng | C6: =$E$1 -> 006 | D6: 192.168.241.33
B7: =$E$2 -> DC Pomezia Housing Mng | C7: =$E$1 -> 006 | D7: 192.168.241.34 | F7: Switch N&C
B8: =$E$2 -> DC Pomezia Housing Mng | C8: =$E$1 -> 006 | D8: 192.168.241.35 | F8: Switch N&C
B9: =$E$2 -> DC Pomezia Housing Mng | C9: =$E$1 -> 006 | D9: 192.168.241.36
B10: =$E$2 -> DC Pomezia Housing Mng | C10: =$E$1 -> 006 | D10: 192.168.241.37
B11: =$E$2 -> DC Pomezia Housing Mng | C11: =$E$1 -> 006 | D11: 192.168.241.38
B12: =$E$2 -> DC Pomezia Housing Mng | C12: =$E$1 -> 006 | D12: 192.168.241.39
B13: =$E$2 -> DC Pomezia Housing Mng | C13: =$E$1 -> 006 | D13: 192.168.241.40
B14: =$E$2 -> DC Pomezia Housing Mng | C14: =$E$1 -> 006 | D14: 192.168.241.41 | F14: switch URG #1 - Pomezia
B15: =$E$2 -> DC Pomezia Housing Mng | C15: =$E$1 -> 006 | D15: 192.168.241.42 | F15: switch URG #2 - Pomezia
B16: =$E$2 -> DC Pomezia Housing Mng | C16: =$E$1 -> 006 | D16: 192.168.241.43
B17: =$E$2 -> DC Pomezia Housing Mng | C17: =$E$1 -> 006 | D17: 192.168.241.44
B18: =$E$2 -> DC Pomezia Housing Mng | C18: =$E$1 -> 006 | D18: 192.168.241.45
B19: =$E$2 -> DC Pomezia Housing Mng | C19: =$E$1 -> 006 | D19: 192.168.241.46
B20: =$E$2 -> DC Pomezia Housing Mng | C20: =$E$1 -> 006 | D20: 192.168.241.47
B21: =$E$2 -> DC Pomezia Housing Mng | C21: =$E$1 -> 006 | D21: 192.168.241.48
B22: =$E$2 -> DC Pomezia Housing Mng | C22: =$E$1 -> 006 | D22: 192.168.241.49
B23: =$E$2 -> DC Pomezia Housing Mng | C23: =$E$1 -> 006 | D23: 192.168.241.50
B24: =$E$2 -> DC Pomezia Housing Mng | C24: =$E$1 -> 006 | D24: 192.168.241.51
B25: =$E$2 -> DC Pomezia Housing Mng | C25: =$E$1 -> 006 | D25: 192.168.241.52
B26: =$E$2 -> DC Pomezia Housing Mng | C26: =$E$1 -> 006 | D26: 192.168.241.53
B27: =$E$2 -> DC Pomezia Housing Mng | C27: =$E$1 -> 006 | D27: 192.168.241.54
... B35: =$E$2 -> DC Pomezia Housing Mng | C35: =$E$1 -> 006 | D35: 192.168.241.62
B36: =$E$2 -> DC Pomezia Housing Mng | C36: =$E$1 -> 006 | D36: 192.168.241.63 | F36: broadcast

Sheet DC S.Stefano Housing Dati
A1: Summary | D1: ID: | E1: =Summary!D11 -> 101 | F1: ='DC Acilia Housing Dati'!F1+1 -> 6
B2: {=MID(CELL("nomefile",A1),FIND("]",CELL("nomefile",A1))+1,255)} -> #VALUE! | D2: Label: | E2: =Summary!B11 -> DC S.Stefano Housing Dati
B4: Label | C4: ID | D4: IP | E4: hostname | F4: Descrizione | G4: Note | H4: OLD_hostname
B5: =$E$2 -> DC S.Stefano Housing Dati | C5: =$E$1 -> 101 | D5: 192.168.230.0 | F5: =VLOOKUP(B2,Summary!B4:E123,2,FALSE) -> #VALUE!
B6: =$E$2 -> DC S.Stefano Housing Dati | C6: =$E$1 -> 101 | D6: 192.168.230.1 | F6: gateway
B7: =$E$2 -> DC S.Stefano Housing Dati | C7: =$E$1 -> 101 | D7: 192.168.230.2
B8: =$E$2 -> DC S.Stefano Housing Dati | C8: =$E$1 -> 101 | D8: 192.168.230.3
B9: =$E$2 -> DC S.Stefano Housing Dati | C9: =$E$1 -> 101 | D9: 192.168.230.4
B10: =$E$2 -> DC S.Stefano Housing Dati | C10: =$E$1 -> 101 | D10: 192.168.230.5
B11: =$E$2 -> DC S.Stefano Housing Dati | C11: =$E$1 -> 101 | D11: 192.168.230.6
B12: =$E$2 -> DC S.Stefano Housing Dati | C12: =$E$1 -> 101 | D12: 192.168.230.7
B13: =$E$2 -> DC S.Stefano Housing Dati | C13: =$E$1 -> 101 | D13: 192.168.230.8
B14: =$E$2 -> DC S.Stefano Housing Dati | C14: =$E$1 -> 101 | D14: 192.168.230.9
B15: =$E$2 -> DC S.Stefano Housing Dati | C15: =$E$1 -> 101 | D15: 192.168.230.10 | E15: ss-rec-tdm1 | F15: Recorder EMERGENZA/URGENZA sito S.STEFANO
B16: =$E$2 -> DC S.Stefano Housing Dati | C16: =$E$1 -> 101 | D16: 192.168.230.11
B17: =$E$2 -> DC S.Stefano Housing Dati | C17: =$E$1 -> 101 | D17: 192.168.230.12
B18: =$E$2 -> DC S.Stefano Housing Dati | C18: =$E$1 -> 101 | D18: 192.168.230.13
B19: =$E$2 -> DC S.Stefano Housing Dati | C19: =$E$1 -> 101 | D19: 192.168.230.14
B20: =$E$2 -> DC S.Stefano Housing Dati | C20: =$E$1 -> 101 | D20: 192.168.230.15
B21: =$E$2 -> DC S.Stefano Housing Dati | C21: =$E$1 -> 101 | D21: 192.168.230.16
B22: =$E$2 -> DC S.Stefano Housing Dati | C22: =$E$1 -> 101 | D22: 192.168.230.17
B23: =$E$2 -> DC S.Stefano Housing Dati | C23: =$E$1 -> 101 | D23: 192.168.230.18
B24: =$E$2 -> DC S.Stefano Housing Dati | C24: =$E$1 -> 101 | D24: 192.168.230.19
B25: =$E$2 -> DC S.Stefano Housing Dati | C25: =$E$1 -> 101 | D25: 192.168.230.20
B26: =$E$2 -> DC S.Stefano Housing Dati | C26: =$E$1 -> 101 | D26: 192.168.230.21
B27: =$E$2 -> DC S.Stefano Housing Dati | C27: =$E$1 -> 101 | D27: 192.168.230.22
... B131: =$E$2 -> DC S.Stefano Housing Dati | C131: =$E$1 -> 101 | D131: 192.168.230.126
B132: =$E$2 -> DC S.Stefano Housing Dati | C132: =$E$1 -> 101 | D132: 192.168.230.127 | F132: broadcast

Sheet DC S.Stefano Housing Voip
A1: Summary | D1: ID: | E1: =Summary!D12 -> 102 | F1: ='DC Acilia Housing Dati'!F1+1 -> 6
B2: {=MID(CELL("nomefile",A1),FIND("]",CELL("nomefile",A1))+1,255)} -> #VALUE! | D2: Label: | E2: =Summary!B12 -> DC S.Stefano Housing Voip
B4: Label | C4: ID | D4: IP | E4: hostname | F4: Descrizione | G4: Note
B5: =$E$2 -> DC S.Stefano Housing Voip | C5: =$E$1 -> 102 | D5: 192168230128 | F5: =VLOOKUP(B2,Summary!B4:E123,2,FALSE) -> #VALUE!
B6: =$E$2 -> DC S.Stefano Housing Voip | C6: =$E$1 -> 102 | D6: 192168230129 | F6: gateway
B7: =$E$2 -> DC S.Stefano Housing Voip | C7: =$E$1 -> 102 | D7: 192168230130 | E7: ss-urg-tel-vipsn1 | F7: VIP /alias SN1 del sito S. Stefano dedicato all'EMERGENZA/URGENZA
